<?xml version="1.0" ?>
<!-- =================================================================================== -->
<!-- |    This document was autogenerated by xacro from src/lab03/lab03_description/urdf/lab03.main.xacro | -->
<!-- |    EDITING THIS FILE BY HAND IS NOT RECOMMENDED                                 | -->
<!-- =================================================================================== -->
<robot name="lab03" xmlns:xacro="http://www.ros.org/wiki/xacro">
  <material name="blue">
    <color rgba="0 0 0.8 1"/>
  </material>
  <material name="black">
    <color rgba="0 0 0 1"/>
  </material>
  <material name="white">
    <color rgba="1 1 1 1"/>
  </material>
  <gazebo>
    <plugin filename="libgazebo_ros_control.so" name="gazebo_ros_control">
      <robotNamespace>/lab03</robotNamespace>
    </plugin>
  </gazebo>
  <link name="base_link"/>
  <link name="robot_chassis">
    <visual>
      <origin rpy="0 0 0" xyz="0 0 0"/>
      <geometry>
        <cylinder length="0.1" radius="0.2"/>
      </geometry>
      <material name="blue"/>
    </visual>
    <collision>
      <origin rpy="0 0 0" xyz="0 0 0"/>
      <geometry>
        <cylinder length="0.1" radius="0.2"/>
      </geometry>
    </collision>
    <inertial>
      <mass value="0.1"/>
      <inertia ixx="8.85416666667e-05" ixy="0" ixz="0" iyy="0.000166666666667" iyz="0" izz="8.85416666667e-05"/>
    </inertial>
  </link>
  <joint name="base_link_joint" type="fixed">
    <origin rpy="0 0 0" xyz="0 0 0.15"/>
    <parent link="base_link"/>
    <child link="robot_chassis"/>
  </joint>
  <link name="left_wheel">
    <visual>
      <origin rpy="1.57079632679 0 0" xyz="0 0 0"/>
      <geometry>
        <sphere radius="0.075"/>
      </geometry>
      <material name="black"/>
    </visual>
    <collision>
      <origin rpy="1.57079632679 0 0" xyz="0 0 0"/>
      <geometry>
        <sphere radius="0.075"/>
      </geometry>
    </collision>
    <inertial>
      <mass value="0.00883572933822"/>
      <origin rpy="1.57079632679 0 0" xyz="0 0 0"/>
      <inertia ixx="1.24436521513e-05" ixy="0" ixz="0" iyy="1.24436521513e-05" iyz="0" izz="2.48504887637e-05"/>
    </inertial>
  </link>
  <joint name="left_wheel_joint" type="continuous">
    <parent link="robot_chassis"/>
    <child link="left_wheel"/>
    <origin xyz="0.125 0 0"/>
    <axis xyz="0 1 0"/>
  </joint>
  <link name="right_wheel">
    <visual>
      <origin rpy="1.57079632679 0 0" xyz="0 0 0"/>
      <geometry>
        <sphere radius="0.075"/>
      </geometry>
      <material name="black"/>
    </visual>
    <collision>
      <origin rpy="1.57079632679 0 0" xyz="0 0 0"/>
      <geometry>
        <sphere radius="0.075"/>
      </geometry>
    </collision>
    <inertial>
      <mass value="0.00883572933822"/>
      <origin rpy="1.57079632679 0 0" xyz="0 0 0"/>
      <inertia ixx="1.24436521513e-05" ixy="0" ixz="0" iyy="1.24436521513e-05" iyz="0" izz="2.48504887637e-05"/>
    </inertial>
  </link>
  <joint name="right_wheel_joint" type="continuous">
    <parent link="robot_chassis"/>
    <child link="right_wheel"/>
    <origin xyz="-0.125 0 0"/>
    <axis xyz="0 1 0"/>
  </joint>
  <link name="front_glide">
    <visual>
      <origin rpy="1.57079632679 0 0" xyz="0 0 0"/>
      <geometry>
        <sphere radius="0.06"/>
      </geometry>
      <material name="white"/>
    </visual>
    <collision>
      <origin rpy="1.57079632679 0 0" xyz="0 0 0"/>
      <geometry>
        <sphere radius="0.06"/>
      </geometry>
    </collision>
    <inertial>
      <mass value="0.00565486677646"/>
      <origin rpy="1.57079632679 0 0" xyz="0 0 0"/>
      <inertia ixx="5.10116107127e-06" ixy="0" ixz="0" iyy="5.10116107127e-06" iyz="0" izz="1.01787601976e-05"/>
    </inertial>
  </link>
  <joint name="front_glide_joint" type="fixed">
    <parent link="robot_chassis"/>
    <child link="front_glide"/>
    <origin xyz="0 0.14 0"/>
    <axis xyz="0 1 0"/>
  </joint>
  <link name="back_glide">
    <visual>
      <origin rpy="1.57079632679 0 0" xyz="0 0 0"/>
      <geometry>
        <sphere radius="0.06"/>
      </geometry>
      <material name="white"/>
    </visual>
    <collision>
      <origin rpy="1.57079632679 0 0" xyz="0 0 0"/>
      <geometry>
        <sphere radius="0.06"/>
      </geometry>
    </collision>
    <inertial>
      <mass value="0.00565486677646"/>
      <origin rpy="1.57079632679 0 0" xyz="0 0 0"/>
      <inertia ixx="5.10116107127e-06" ixy="0" ixz="0" iyy="5.10116107127e-06" iyz="0" izz="1.01787601976e-05"/>
    </inertial>
  </link>
  <joint name="back_glide_joint" type="fixed">
    <parent link="robot_chassis"/>
    <child link="back_glide"/>
    <origin xyz="0 -0.14 0"/>
    <axis xyz="0 1 0"/>
  </joint>
</robot>

