<sdf version='1.6'>
  <model name='lab03'>
    <link name='base_link'>
      <pose frame=''>0 0 0 0 -0 0</pose>
      <inertial>
        <pose frame=''>0 -0 0.15 0 -0 0</pose>
        <mass>0.11131</mass>
        <inertia>
          <ixx>0.000320415</ixx>
          <ixy>0</ixy>
          <ixz>0</ixz>
          <iyy>0.000187024</iyy>
          <iyz>-4.97258e-17</iyz>
          <izz>0.000320415</izz>
        </inertia>
      </inertial>
      <collision name='base_link_fixed_joint_lump__robot_chassis_collision'>
        <pose frame=''>0 0 0.15 0 -0 0</pose>
        <geometry>
          <cylinder>
            <length>0.1</length>
            <radius>0.2</radius>
          </cylinder>
        </geometry>
      </collision>
      <collision name='base_link_fixed_joint_lump__back_glide_collision_1'>
        <pose frame=''>0 -0.14 0.15 1.5708 -0 0</pose>
        <geometry>
          <sphere>
            <radius>0.06</radius>
          </sphere>
        </geometry>
      </collision>
      <collision name='base_link_fixed_joint_lump__front_glide_collision_2'>
        <pose frame=''>0 0.14 0.15 1.5708 -0 0</pose>
        <geometry>
          <sphere>
            <radius>0.06</radius>
          </sphere>
        </geometry>
      </collision>
      <visual name='base_link_fixed_joint_lump__robot_chassis_visual'>
        <pose frame=''>0 0 0.15 0 -0 0</pose>
        <geometry>
          <cylinder>
            <length>0.1</length>
            <radius>0.2</radius>
          </cylinder>
        </geometry>
      </visual>
      <visual name='base_link_fixed_joint_lump__back_glide_visual_1'>
        <pose frame=''>0 -0.14 0.15 1.5708 -0 0</pose>
        <geometry>
          <sphere>
            <radius>0.06</radius>
          </sphere>
        </geometry>
      </visual>
      <visual name='base_link_fixed_joint_lump__front_glide_visual_2'>
        <pose frame=''>0 0.14 0.15 1.5708 -0 0</pose>
        <geometry>
          <sphere>
            <radius>0.06</radius>
          </sphere>
        </geometry>
      </visual>
    </link>
    <link name='left_wheel'>
      <pose frame=''>0.125 0 0.15 0 -0 0</pose>
      <inertial>
        <pose frame=''>0 0 0 1.5708 -0 0</pose>
        <mass>0.00883573</mass>
        <inertia>
          <ixx>1.24437e-05</ixx>
          <ixy>0</ixy>
          <ixz>0</ixz>
          <iyy>1.24437e-05</iyy>
          <iyz>0</iyz>
          <izz>2.48505e-05</izz>
        </inertia>
      </inertial>
      <collision name='left_wheel_collision'>
        <pose frame=''>0 0 0 1.5708 -0 0</pose>
        <geometry>
          <sphere>
            <radius>0.075</radius>
          </sphere>
        </geometry>
      </collision>
      <visual name='left_wheel_visual'>
        <pose frame=''>0 0 0 1.5708 -0 0</pose>
        <geometry>
          <sphere>
            <radius>0.075</radius>
          </sphere>
        </geometry>
      </visual>
    </link>
    <joint name='left_wheel_joint' type='revolute'>
      <child>left_wheel</child>
      <parent>base_link</parent>
      <axis>
        <xyz>0 1 0</xyz>
        <limit>
          <lower>-1e+16</lower>
          <upper>1e+16</upper>
        </limit>
        <dynamics>
          <spring_reference>0</spring_reference>
          <spring_stiffness>0</spring_stiffness>
        </dynamics>
        <use_parent_model_frame>1</use_parent_model_frame>
      </axis>
    </joint>
    <link name='right_wheel'>
      <pose frame=''>-0.125 0 0.15 0 -0 0</pose>
      <inertial>
        <pose frame=''>0 0 0 1.5708 -0 0</pose>
        <mass>0.00883573</mass>
        <inertia>
          <ixx>1.24437e-05</ixx>
          <ixy>0</ixy>
          <ixz>0</ixz>
          <iyy>1.24437e-05</iyy>
          <iyz>0</iyz>
          <izz>2.48505e-05</izz>
        </inertia>
      </inertial>
      <collision name='right_wheel_collision'>
        <pose frame=''>0 0 0 1.5708 -0 0</pose>
        <geometry>
          <sphere>
            <radius>0.075</radius>
          </sphere>
        </geometry>
      </collision>
      <visual name='right_wheel_visual'>
        <pose frame=''>0 0 0 1.5708 -0 0</pose>
        <geometry>
          <sphere>
            <radius>0.075</radius>
          </sphere>
        </geometry>
      </visual>
    </link>
    <joint name='right_wheel_joint' type='revolute'>
      <child>right_wheel</child>
      <parent>base_link</parent>
      <axis>
        <xyz>0 1 0</xyz>
        <limit>
          <lower>-1e+16</lower>
          <upper>1e+16</upper>
        </limit>
        <dynamics>
          <spring_reference>0</spring_reference>
          <spring_stiffness>0</spring_stiffness>
        </dynamics>
        <use_parent_model_frame>1</use_parent_model_frame>
      </axis>
    </joint>
    <static>0</static>
    <plugin name='gazebo_ros_control' filename='libgazebo_ros_control.so'>
      <robotNamespace>/lab03</robotNamespace>
    </plugin>
  </model>
</sdf>
