<?xml version="1.0"?>
<robot xmlns:xacro="http://www.ros.org/wiki/xacro" name="diff_drive_robot">

<xacro:property name="wheel_radius" value="0.05" />
<xacro:property name="glider_radius" value="0.04" />
<xacro:arg name="chassis_radius" default="0.2" />

<link name="base_link" />


	<material name="blue">
    	<color rgba="0 0 0.8 1"/>
  	</material>
  	<material name="black">
    	<color rgba="0 0 0 1"/>
  	</material>
  	<material name="white">
    	<color rgba="1 1 1 1"/>
  	</material>

    <link name="robot_chasis">
        <visual>
            <geometry>
                <cylinder length="0.1" radius="${arg chassis_radius}"/>
            </geometry>
            <material name="blue"/>
        </visual>
    </link>

    <joint name="chassis_joint" type="fixed">
        <parent link="base_link"/>
        <child link="robot_chasis"/>
        <origin xyz="0 0 0.5"/>
    </joint>

    <link name="left_wheel">
    	<visual>
    		<geometry>
    			<sphere length=".05" radius="${wheel_radius}"/>
    		</geometry>
    	<material name="black"/>
    	</visual>
    </link>

    <joint name="base_to_left_wheel" type="continuous">
    	<parent link="robot_chasis"/>
    	<child link="left_wheel"/>
    	<origin xyz="-.15 0.0 -0.06"/>
  	</joint>

  	<link name="right_wheel">
    	<visual>
    		<geometry>
    			<sphere length=".05" radius="${wheel_radius}"/>
    		</geometry>
    	<material name="black"/>	
    	</visual>
    </link>

    <joint name="base_to_right_wheel" type="continuous">
    	<parent link="robot_chasis"/>
    	<child link="right_wheel"/>
    	<origin xyz="0.15 0.0 -0.06"/>
  	</joint>

  	<link name="back_wheel">
    	<visual>
    		<geometry>
    			<sphere length=".05" radius="${glider_radius}"/>
    		</geometry>
    	<material name="white"/>	
    	</visual>
    </link>

    <joint name="base_to_front_wheel" type="fixed">
    	<parent link="robot_chasis"/>
    	<child link="back_wheel"/>
    	<origin xyz="0 -0.15 -0.08"/>
  	</joint>

  	<link name="front_wheel">
    	<visual>
    		<geometry>
    			<sphere length=".05" radius="${glider_radius}"/>
    		</geometry>
    	<material name="white"/>	
    	</visual>
    </link>

    <joint name="base_to_back_wheel" type="fixed">
    	<parent link="robot_chasis"/>
    	<child link="front_wheel"/>
    	<origin xyz="0 0.15 -0.08"/>
  	</joint>

</robot>
